package readren.taskflow

import Doer.ExceptionReport

import munit.ScalaCheckEffectSuite
import org.scalacheck.Arbitrary
import org.scalacheck.effect.PropF

import java.util.concurrent.atomic.AtomicInteger
import java.util.concurrent.{Executors, TimeUnit}
import scala.collection.mutable
import scala.concurrent.ExecutionContext.Implicits.global
import scala.concurrent.duration.FiniteDuration
import scala.concurrent.{Await, Future}
import scala.util.control.NonFatal
import scala.util.{Failure, Success, Try}

class DoerTestEffect extends ScalaCheckEffectSuite {

	/** Remembers the exceptions that were unhandled in the DoSiThEx's thread.
	 * CAUTION: this variable should be accessed within the DoSiThEx thread only. */
	private val unhandledExceptions = mutable.Set.empty[String]
	private val reportedExceptions = mutable.Set.empty[String]

	private val assistant = new Doer.Assistant {
		private val doSiThEx = Executors.newSingleThreadExecutor()

		private val sequencer: AtomicInteger = new AtomicInteger(0)

		override def queueForSequentialExecution(runnable: Runnable): Unit = {
			val id = sequencer.addAndGet(1)
			// println(s"queuedForSequentialExecution: pre execute; id=$id, thread=${Thread.currentThread().getName}; runnable=$runnable")
			doSiThEx.execute(() => {
				// println(s"queuedForSequentialExecution: pre run; id=$id; thread=${Thread.currentThread().getName}")
				try {
					runnable.run()
					// println(s"queuedForSequentialExecution: run completed normally; id=$id; thread=${Thread.currentThread().getName}")
				}
				catch {
					case cause: Throwable =>
						// println(s"queuedForSequentialExecution: run completed abruptly with: $cause; id=$id; thread=${Thread.currentThread().getName}")
						unhandledExceptions.addOne(cause.getMessage);
						throw cause;
				} finally {
					// println(s"queuedForSequentialExecution: finally; id=$id; thread=${Thread.currentThread().getName}")
				}
			})
		}

		override def reportFailure(failure: Throwable): Unit = {
			// println(s"Reporting failure to munit: ${failure.getMessage}")
			munitExecutionContext.reportFailure(failure)
			doSiThEx.execute { () =>
				val exceptionToReport = if failure.isInstanceOf[ExceptionReport] then failure.getCause else failure
				reportedExceptions.addOne(exceptionToReport.getMessage)
			}
		}

	}

	private val doer: Doer = new Doer(assistant) {}

	import doer.*

	private val shared = new DoerTestShared[doer.type](doer)
	import shared.{*, given}

	////////// DUTY //////////

	// Custom equality for Duty based on the result
	private def checkEquality[A](duty1: Duty[A], duty2: Duty[A]): Future[Unit] = {
		// println(s"Begin: duty1=$duty1, duty2=$duty2")
		val futureEquality = for {
			a1 <- duty1.toFutureHardy()
			a2 <- duty2.toFutureHardy()
		} yield {
			// println(s"$try1 ==== $try2")
			a1 == a2
		}
		futureEquality.map(assert(_))
	}
	
	// Monadic left identity law: Duty.ready(x).flatMap(f) == f(x)
	test("Duty: left identity") {
		PropF.forAllF { (x: Int, f: Int => Duty[Int]) =>
			val left = Duty.ready(x).flatMap(f)
			val right = f(x)
			checkEquality(left, right)
		}
	}

	// Monadic right identity law: m.flatMap(Duty.ready) == m
	test("Duty: right identity") {
		PropF.forAllF { (m: Duty[Int]) =>
			val left = m.flatMap(Duty.ready)
			val right = m
			checkEquality(left, right)
		}
	}

	// Monadic associativity law: m.flatMap(f).flatMap(g) == m.flatMap(x => f(x).flatMap(g))
	test("Duty: associativity") {
		PropF.forAllF { (m: Duty[Int], f: Int => Duty[Int], g: Int => Duty[Int]) =>
			val leftAssoc = m.flatMap(f).flatMap(g)
			val rightAssoc = m.flatMap(x => f(x).flatMap(g))
			checkEquality(leftAssoc, rightAssoc)
		}
	}

	// Functor: `m.map(f) == m.flatMap(a => ready(f(a)))`
	test("Duty: can be transformed with map") {
		PropF.forAllF { (m: Duty[Int], f: Int => String) =>
			val left = m.map(f)
			val right = m.flatMap(a => Duty.ready(f(a)))
			checkEquality(left, right)
		}
	}

	test("Duty: any can be combined") {
		PropF.forAllF { (dutyA: Duty[Int], dutyB: Duty[Int], f: (Int, Int) => Int) =>
			val combinedDuty = Duty.combine(dutyA, dutyB)(f)

			for {
				combinedResult <- combinedDuty.toFutureHardy()
				dutyAResult <- dutyA.toFutureHardy()
				dutyBResult <- dutyB.toFutureHardy()
			} yield {
				assert(combinedResult == f(dutyAResult, dutyBResult))
			}
		}
	}
	
	
	////////// TASK /////////////

	// Custom equality for Task based on the result of attempt
	private def checkEquality[A](task1: Task[A], task2: Task[A]): Future[Unit] = {
		val futureEquality = for {
			try1 <- task1.toFutureHardy()
			try2 <- task2.toFutureHardy()
		} yield {
			// println(s"$try1 ==== $try2")
			try1 ==== try2
		}
		futureEquality.map(assert(_))
	}

//	private def evalNow[A](task: Task[A]): Try[A] = {
//		Await.result(task.toFutureHardy(), new FiniteDuration(1, TimeUnit.MINUTES))
//	}
	
	
	// Monadic left identity law: Task.successful(x).flatMap(f) == f(x)
	test("Task: left identity") {
		PropF.forAllF { (x: Int, f: Int => Task[Int]) =>
			val sx = Task.successful(x)
			val left = Task.successful(x).flatMap(f)
			val right = f(x)
			checkEquality(left, right)
		}
	}

	// Monadic right identity law: m.flatMap(Task.successful) == m
	test("Task: right identity") {
		PropF.forAllF { (m: Task[Int]) =>
			val left = m.flatMap(Task.successful)
			val right = m
			checkEquality(left, right)
		}
	}

	// Monadic associativity law: m.flatMap(f).flatMap(g) == m.flatMap(x => f(x).flatMap(g))
	test("Task: associativity") {
		PropF.forAllF { (m: Task[Int], f: Int => Task[Int], g: Int => Task[Int]) =>
			val leftAssoc = m.flatMap(f).flatMap(g)
			val rightAssoc = m.flatMap(x => f(x).flatMap(g))
			checkEquality(leftAssoc, rightAssoc)
		}
	}

	// Functor: `m.map(f) == m.flatMap(a => unit(f(a)))`
	test("Task: can be transformed with map") {
		PropF.forAllF { (m: Task[Int], f: Int => String) =>
			val left = m.map(f)
			val right = m.flatMap(a => Task.successful(f(a)))
			checkEquality(left, right)
		}
	}

	// Recovery: `failedTask.recover(f) == if f.isDefinedAt(e) then successful(f(e)) else failed(e)` where e is the exception thrown by failedTask
	test("Task: can be recovered from failure") {
		PropF.forAllF { (e: Throwable, f: PartialFunction[Throwable, Int]) =>
			if NonFatal(e) then {
				val leftTask = Task.failed[Int](e).recover(f)
				val rightTask = if f.isDefinedAt(e) then Task.successful(f(e)) else Task.failed(e);
				checkEquality(leftTask, rightTask)
			} else Future.successful(())
		}
	}

	test("Task: any can be combined") {
		PropF.forAllF { (taskA: Task[Int], taskB: Task[Int], f: (Try[Int], Try[Int]) => Try[Int]) =>
			val combinedTask = Task.combine(taskA, taskB)(f)

			for {
				combinedResult <- combinedTask.toFutureHardy()
				taskAResult <- taskA.toFutureHardy()
				taskBResult <- taskB.toFutureHardy()
			} yield {
				assert(combinedResult ==== f(taskAResult, taskBResult))
			}
		}
	}

	private val sleep1ms = Task.alien { () =>
		Future {
			Thread.sleep(1)
		}(global)
	}


	test("if a Task's transformation throws an exception the task should complete with that exception if it is non-fatal, or never complete if it is fatal.") {
		PropF.forAllF { (task: Task[Int], exception: Throwable) =>

			/** Do the test for a single operation */
			def check(operation: Task[Int] => Task[Int]): Future[Boolean] = {
				// Apply the operation to the random task. The `recover` is to ensure that the random task completes successfully in order for the operation to always be evaluated.
				val future = operation {
					task.recover { case cause => exception.getMessage.hashCode }
				}.toFutureHardy()

				// Build a task that completes with `true` as soon as the `exception` is found among the unhandled exceptions logged in the `unhandledExceptions` set; or `false` if it isn't found after 99 milliseconds.
				val exceptionWasNotHandled = sleep1ms
					// Check if the thread of DoSiThEx was terminated abruptly due to an unhandled exception
					.flatMap { _ =>
						Task.mine { () => unhandledExceptions.remove(exception.getMessage) }
					}
					// repeat the previous until the exception is found among the unhandled exceptions but no more than 99 times.
					.reiteratedUntilSome() { (tries, theExceptionWasFoundAmongTheUnhandledOnes) =>
						if theExceptionWasFoundAmongTheUnhandledOnes then Maybe.some(Success(true))
						else if tries > 99 then Maybe.some(Success(false))
						else Maybe.empty
					}.toFuture()

				// Depending on the kind of exception, fatal or not, the check is very different.
				if NonFatal(exception) then {
					// When the exception is non-fatal the task should complete with a Failure containing the exception thrown by the transformation.
					val nonFatalWasHandled: Future[Boolean] = future.map {
						case Failure(`exception`) => true
						case Failure(wrapper) if wrapper.getCause eq exception => true
						case result =>
							throw new AssertionError(s"The task completed but with an unexpected result. Expected: ${Failure(exception)}, Actual: $result")
					}
					Future.firstCompletedOf(List(nonFatalWasHandled, exceptionWasNotHandled.map { wasNotHandled =>
						assert(!wasNotHandled, "A non fatal was not handled despite is should.")
						false
					}))
				} else {
					// When the exception is fatal it should remain unhandled, causing the doSiThEx thread to terminate. Consequently, the exception will be logged in the unhandledExceptions set, and the task and associated Future will never complete.
					// The following future will complete with `false` if the fatal exception was handled. Otherwise, it will never complete.
					val fatalWasHandled = future.map { result =>
						// println(s"Was handled somehow: result=$result")
						throw new AssertionError(s"The task completed despite it shouldn't. Result=$result")
					}


					// The result of only one of the two futures, `fatalWasHandled` and `exceptionWasNotHandled`, is enough to know if the check is passed. So get the result of the one that completes first.
					Future.firstCompletedOf(List(fatalWasHandled, exceptionWasNotHandled.map { wasNotHandled =>
						assert(wasNotHandled, "The task handled the fatal exception despite it shouldn't");
						true
					}))
				}

			}

			def f0[A](): A = throw exception
			def f1[A, B](a: A): B = throw exception

			def f2[A, B, C](a: A, b: B): C = throw exception

			// println(s"Begin: task=$task, exception=$exception")

			for {
				foreachTestResult <- check(_.foreach(_ => throw exception).map(_ => 0))
				mapTestResult <- check(_.map(f1))
				flatMapTestResult <- check(_.flatMap(f1))
				withFilterTestResult <- check(_.withFilter(f1))
				transformTestResult <- check(_.transform(f1))
				transformWithTestResult <- check(_.transformWith(f1))
				recoverTestResult <- check(_.transform { _ => Failure(new Exception("for recover")) }.recover(f1))
				recoverWithTestResult <- check(_.transform { _ => Failure(new Exception("for recoverWith")) }.recoverWith(f1))
				repeatedHardyUntilSomeTestResult <- check(_.reiteratedHardyUntilSome()(f2))
				repeatedUntilSomeTestResult <- check(_.reiteratedUntilSome()(f2))
				repeatedUntilDefinedTestResult <- check(_.reiteratedHardyUntilDefined()(f2))
				repeatedWhileNoneTestResult <- check(_.reiteratedWhileEmpty(Success(0))(f2))
				repeatedWhileUndefinedTestResult <- check(_.reiteratedWhileUndefined(Success(0))(f2))
				ownTestResult <- check(_.flatMap(_ => Task.own(f0)))
				ownFlatTestResult <- check(_.flatMap(_ => Task.ownFlat(f0)))
				alienTestResult <- check(_.flatMap(_ => Task.alien(f0)))
			} yield
				assert(
					foreachTestResult
						&& mapTestResult
						&& flatMapTestResult
						&& withFilterTestResult
						&& transformTestResult
						&& transformWithTestResult
						&& recoverTestResult
						&& recoverWithTestResult
						&& repeatedHardyUntilSomeTestResult
						&& repeatedUntilSomeTestResult
						&& repeatedUntilDefinedTestResult
						&& repeatedWhileNoneTestResult
						&& repeatedWhileUndefinedTestResult
						&& ownTestResult
						&& ownFlatTestResult
						&& alienTestResult,
					s"""
					   |foreach: $foreachTestResult
					   |map: $mapTestResult
					   |flatMap: $flatMapTestResult
					   |withFilter: $withFilterTestResult
					   |transform: $transformTestResult
					   |transformWith: $transformWithTestResult
					   |recover: $recoverTestResult
					   |recoverWith: $recoverWithTestResult
					   |repeatedHardyUntilSome: $repeatedHardyUntilSomeTestResult
					   |repeatedUntilSome: $repeatedUntilSomeTestResult
					   |repeatedUntilDefined: $repeatedUntilDefinedTestResult
					   |repeatedWhileNone: $repeatedWhileNoneTestResult
					   |repeatedWhileUndefined: $repeatedWhileUndefinedTestResult
					   |own: $ownTestResult
					   |ownFlat: $ownFlatTestResult
					   |alien: $alienTestResult""".stripMargin
				)
			// TODO add a test to check if Task.andThen effect-full function is guarded.
		}
	}

	test("`Task.engage` should either report or not catch exceptions thrown by `onComplete`") {
		PropF.forAllF { (task: Task[Int], exception: Throwable) =>

			/** Do the test for a single operation */
			def check[R](operation: Task[Int] => Task[R]): Future[Boolean] = {
				// Apply the operation to the random task and trigger the execution passing a faulty on-complete callback.
				operation(task).trigger()(tryR => throw exception)

				// Build and execute a task that completes with `true` as soon as the `exception` is found among the unhandled exceptions logged in the `unhandledExceptions` set; or `false` if it isn't found after 99 milliseconds.
				sleep1ms
					// Check if the exception was reported or unhandled
					.flatMap { _ =>
						Task.mine { () => unhandledExceptions.remove(exception.getMessage) || reportedExceptions.remove(exception.getMessage) }
					}
					// repeat the previous until the exception is found among the unhandled exceptions but no more than 99 times.
					.reiteratedUntilSome() { (tries, theExceptionWasFoundAmongTheUnhandledOnes) =>
						if theExceptionWasFoundAmongTheUnhandledOnes then {
							// println(s"The exception was found among the unhandled or reported exceptions")
							Maybe.some(Success(true))
						}
						else if tries > 99 then {
							// println(s"The exception was NOT found among the unhandled/reported exceptions after $tries retries. Waiting aborted.")
							Maybe.some(Success(false))
						}
						else {
							// println(s"The exception was NOT found among the unhandled/reported exceptions after $tries retries. Wait more time.")
							Maybe.empty
						}
					}.toFuture()
			}

			val randomInt = exception.getMessage.hashCode()
			val smallNonNegativeInt = randomInt % 9
			val randomBool = (randomInt % 2) == 0
			val randomTryInt = if randomBool then Success(randomInt) else Failure(exception)
			// println(s"Begin: task=$task, exception=$exception, randomInt=$randomInt, randomBool=$randomBool")

			for {
				factoryTestResult <- check(identity)
				foreachTestResult <- check(_.foreach(_ => ()))
				mapTestResult <- check(_.map(identity))
				flatMapTestResult <- check(_.flatMap(_ => task))
				withFilterTestResult <- check(_.withFilter(_ => randomBool))
				consumeTestResult <- check(_.consume(_ => ()))
				andThenTestResult <- check(_.andThen(_ => ()))
				transformTestResult <- check(_.transform(identity))
				transformWithTestResult <- check(_.transformWith(_ => task))
				recoverTestResult <- check(_.recover { case x if randomBool => randomInt })
				recoverWithTestResult <- check(_.recoverWith { case x if randomBool => task })
				repeatedHardyUntilSomeTestResult <- check(_.reiteratedHardyUntilSome() { (n, tryInt) => if n > smallNonNegativeInt then Maybe.some(randomTryInt) else Maybe.empty })
				repeatedUntilSomeTestResult <- check(_.reiteratedUntilSome() { (n, i) => if n > smallNonNegativeInt then Maybe.some(randomTryInt) else Maybe.empty })
				repeatedUntilDefinedTestResult <- check(_.reiteratedHardyUntilDefined() { case (n, tryInt) if n > smallNonNegativeInt => tryInt })
				repeatedWhileNoneTestResult <- check(_.reiteratedWhileEmpty(Success(0)) { (n, tryInt) => if n > smallNonNegativeInt then Maybe.some(randomTryInt) else Maybe.empty })
				repeatedWhileUndefinedTestResult <- check(_.reiteratedWhileUndefined(Success(0)) { case (n, tryInt) if n > smallNonNegativeInt => randomInt })
			} yield
				assert(
					factoryTestResult
						&& foreachTestResult
						&& mapTestResult
						&& flatMapTestResult
						&& withFilterTestResult
						&& consumeTestResult
						&& andThenTestResult
						&& transformTestResult
						&& transformWithTestResult
						&& recoverTestResult
						&& recoverWithTestResult
						&& repeatedHardyUntilSomeTestResult
						&& repeatedUntilSomeTestResult
						&& repeatedUntilDefinedTestResult
						&& repeatedWhileNoneTestResult
						&& repeatedWhileUndefinedTestResult,
					s"""
					   |factory: $factoryTestResult
					   |foreach: $foreachTestResult
					   |map: $mapTestResult
					   |flatMap: $flatMapTestResult
					   |withFilter: $withFilterTestResult
					   |consume: $consumeTestResult
					   |andThen: $andThenTestResult
					   |transform: $transformTestResult
					   |transformWith: $transformWithTestResult
					   |recover: $recoverTestResult
					   |recoverWith: $recoverWithTestResult
					   |repeatedHardyUntilSome: $repeatedHardyUntilSomeTestResult
					   |repeatedUntilSome: $repeatedUntilSomeTestResult
					   |repeatedUntilDefined: $repeatedUntilDefinedTestResult
					   |repeatedWhileNone: $repeatedWhileNoneTestResult
					   |repeatedWhileUndefined: $repeatedWhileUndefinedTestResult
				""".stripMargin
				)
		}
	}

	test("`Duty.engage` should either report or not catch exceptions thrown by `onComplete`") {
		PropF.forAllF { (duty: Duty[Int], exception: Throwable) =>

			/** Do the test for a single operation */
			def check[R](operation: Duty[Int] => Duty[R]): Future[Boolean] = {
				// Apply the operation to the random duty and trigger the execution passing a faulty on-complete callback.
				operation(duty).trigger()(r => throw exception)

				// Build and execute a duty that completes with `true` as soon as the `exception` is found among the unhandled exceptions logged in the `unhandledExceptions` set; or `false` if it isn't found after 99 milliseconds.
				sleep1ms
					// Check if the exception was reported or unhandled
					.flatMap { _ =>
						Task.mine { () => unhandledExceptions.remove(exception.getMessage) || reportedExceptions.remove(exception.getMessage) }
					}
					// repeat the previous until the exception is found among the unhandled exceptions but no more than 99 times.
					.reiteratedUntilSome() { (tries, theExceptionWasFoundAmongTheUnhandledOnes) =>
						if theExceptionWasFoundAmongTheUnhandledOnes then {
							// println(s"The exception was found among the unhandled or reported exceptions")
							Maybe.some(Success(true))
						}
						else if tries > 99 then {
							// println(s"The exception was NOT found among the unhandled/reported exceptions after $tries retries. Waiting aborted.")
							Maybe.some(Success(false))
						}
						else {
							// println(s"The exception was NOT found among the unhandled/reported exceptions after $tries retries. Wait more time.")
							Maybe.empty
						}
					}.toFuture()
			}

			val randomInt = exception.getMessage.hashCode()
			val smallNonNegativeInt = randomInt % 9
			// println(s"Begin: duty=$duty, exception=$exception")

			for {
				factoryTestResult <- check(identity)
				foreachTestResult <- check(_.foreach(_ => ()))
				mapTestResult <- check(_.map(identity))
				flatMapTestResult <- check(_.flatMap(_ => duty))
				andThenTestResult <- check(_.andThen(_ => ()))
				repeatedUntilSomeTestResult <- check(_.repeatedUntilSome() { (n, i) => if n > smallNonNegativeInt then Maybe.some(randomInt) else Maybe.empty })
				repeatedUntilDefinedTestResult <- check(_.repeatedUntilDefined() { case (n, tryInt) if n > smallNonNegativeInt => tryInt })
				repeatedWhileNoneTestResult <- check(_.repeatedWhileEmpty(Success(0)) { (n, tryInt) => if n > smallNonNegativeInt then Maybe.some(randomInt) else Maybe.empty })
				repeatedWhileUndefinedTestResult <- check(_.repeatedWhileUndefined(Success(0)) { case (n, tryInt) if n > smallNonNegativeInt => randomInt })
			} yield
				assert(
					factoryTestResult
						&& foreachTestResult
						&& mapTestResult
						&& flatMapTestResult
						&& andThenTestResult
						&& repeatedUntilSomeTestResult
						&& repeatedUntilDefinedTestResult
						&& repeatedWhileNoneTestResult
						&& repeatedWhileUndefinedTestResult,
					s"""
					   |factory: $factoryTestResult
					   |foreach: $foreachTestResult
					   |map: $mapTestResult
					   |flatMap: $flatMapTestResult
					   |andThen: $andThenTestResult
					   |repeatedUntilSome: $repeatedUntilSomeTestResult
					   |repeatedUntilDefined: $repeatedUntilDefinedTestResult
					   |repeatedWhileNone: $repeatedWhileNoneTestResult
					   |repeatedWhileUndefined: $repeatedWhileUndefinedTestResult
					   |""".stripMargin
				)
		}
	}

}